Workbook

Sheet Sayfa1
A1: MARKA | B1: BrandId | C1: SeasonId | D1: FreeFieldThree | E1: Tema Adı | F1: ThemeId | G1: Kategori | H1: SubCategoryId | I1: Opt Say
A2: IPEKYOL | B2: 4 | C2: 10 | D2: SEMI PLAN | E2: B-BCT2 | F2: =VLOOKUP(E2,Sayfa2!A:B,2,0) -> 1293 | G2: BLUZ | H2: =VLOOKUP(G2,Sayfa2!M:N,2,0) -> 21 | I2: 1
A3: IPEKYOL | B3: 4 | C3: 10 | D3: SEMI PLAN | E3: B-BCT2 | F3: =VLOOKUP(E3,Sayfa2!A:B,2,0) -> 1293 | G3: CEKET | H3: =VLOOKUP(G3,Sayfa2!M:N,2,0) -> 19 | I3: 3
A4: IPEKYOL | B4: 4 | C4: 10 | D4: SEMI PLAN | E4: B-BCT2 | F4: =VLOOKUP(E4,Sayfa2!A:B,2,0) -> 1293 | G4: ELBISE | H4: =VLOOKUP(G4,Sayfa2!M:N,2,0) -> 20 | I4: 2
A5: IPEKYOL | B5: 4 | C5: 10 | D5: SEMI PLAN | E5: B-BCT2 | F5: =VLOOKUP(E5,Sayfa2!A:B,2,0) -> 1293 | G5: ETEK | H5: =VLOOKUP(G5,Sayfa2!M:N,2,0) -> 12 | I5: 2
A6: IPEKYOL | B6: 4 | C6: 10 | D6: SEMI PLAN | E6: B-BCT2 | F6: =VLOOKUP(E6,Sayfa2!A:B,2,0) -> 1293 | G6: GOMLEK | H6: =VLOOKUP(G6,Sayfa2!M:N,2,0) -> 49 | I6: 1
A7: IPEKYOL | B7: 4 | C7: 10 | D7: SEMI PLAN | E7: B-BCT2 | F7: =VLOOKUP(E7,Sayfa2!A:B,2,0) -> 1293 | G7: JEAN PANTOLON | H7: =VLOOKUP(G7,Sayfa2!M:N,2,0) -> 13
A8: IPEKYOL | B8: 4 | C8: 10 | D8: SEMI PLAN | E8: B-BCT2 | F8: =VLOOKUP(E8,Sayfa2!A:B,2,0) -> 1293 | G8: KABAN | H8: =VLOOKUP(G8,Sayfa2!M:N,2,0) -> 16 | I8: 1
A9: IPEKYOL | B9: 4 | C9: 10 | D9: SEMI PLAN | E9: B-BCT2 | F9: =VLOOKUP(E9,Sayfa2!A:B,2,0) -> 1293 | G9: MONT | H9: =VLOOKUP(G9,Sayfa2!M:N,2,0) -> 17
A10: IPEKYOL | B10: 4 | C10: 10 | D10: SEMI PLAN | E10: B-BCT2 | F10: =VLOOKUP(E10,Sayfa2!A:B,2,0) -> 1293 | G10: PANTOLON | H10: =VLOOKUP(G10,Sayfa2!M:N,2,0) -> 14 | I10: 2
A11: IPEKYOL | B11: 4 | C11: 10 | D11: SEMI PLAN | E11: B-BCT2 | F11: =VLOOKUP(E11,Sayfa2!A:B,2,0) -> 1293 | G11: SUNI KURK | H11: =VLOOKUP(G11,Sayfa2!M:N,2,0) -> 52
A12: IPEKYOL | B12: 4 | C12: 10 | D12: SEMI PLAN | E12: B-BCT2 | F12: =VLOOKUP(E12,Sayfa2!A:B,2,0) -> 1293 | G12: SWEATSHIRT | H12: =VLOOKUP(G12,Sayfa2!M:N,2,0) -> 27
A13: IPEKYOL | B13: 4 | C13: 10 | D13: SEMI PLAN | E13: B-BCT2 | F13: =VLOOKUP(E13,Sayfa2!A:B,2,0) -> 1293 | G13: TISORT | H13: =VLOOKUP(G13,Sayfa2!M:N,2,0) -> 22 | I13: 2
A14: IPEKYOL | B14: 4 | C14: 10 | D14: SEMI PLAN | E14: B-BCT2 | F14: =VLOOKUP(E14,Sayfa2!A:B,2,0) -> 1293 | G14: TRIKO | H14: =VLOOKUP(G14,Sayfa2!M:N,2,0) -> 23 | I14: 2
A15: IPEKYOL | B15: 4 | C15: 10 | D15: SEMI PLAN | E15: B-BCT2 | F15: =VLOOKUP(E15,Sayfa2!A:B,2,0) -> 1293 | G15: TULUM | H15: =VLOOKUP(G15,Sayfa2!M:N,2,0) -> 25
A16: IPEKYOL | B16: 4 | C16: 10 | D16: SEMI PLAN | E16: B-BCT2 | F16: =VLOOKUP(E16,Sayfa2!A:B,2,0) -> 1293 | G16: YELEK | H16: =VLOOKUP(G16,Sayfa2!M:N,2,0) -> 50
A17: IPEKYOL | B17: 4 | C17: 10 | D17: SEMI PLAN | E17: Mono-Weekend Edit | F17: =VLOOKUP(E17,Sayfa2!A:B,2,0) -> 1326 | G17: BLUZ | H17: =VLOOKUP(G17,Sayfa2!M:N,2,0) -> 21
A18: IPEKYOL | B18: 4 | C18: 10 | D18: SEMI PLAN | E18: Mono-Weekend Edit | F18: =VLOOKUP(E18,Sayfa2!A:B,2,0) -> 1326 | G18: CEKET | H18: =VLOOKUP(G18,Sayfa2!M:N,2,0) -> 19
A19: IPEKYOL | B19: 4 | C19: 10 | D19: SEMI PLAN | E19: Mono-Weekend Edit | F19: =VLOOKUP(E19,Sayfa2!A:B,2,0) -> 1326 | G19: ELBISE | H19: =VLOOKUP(G19,Sayfa2!M:N,2,0) -> 20
A20: IPEKYOL | B20: 4 | C20: 10 | D20: SEMI PLAN | E20: Mono-Weekend Edit | F20: =VLOOKUP(E20,Sayfa2!A:B,2,0) -> 1326 | G20: ETEK | H20: =VLOOKUP(G20,Sayfa2!M:N,2,0) -> 12
A21: IPEKYOL | B21: 4 | C21: 10 | D21: SEMI PLAN | E21: Mono-Weekend Edit | F21: =VLOOKUP(E21,Sayfa2!A:B,2,0) -> 1326 | G21: GOMLEK | H21: =VLOOKUP(G21,Sayfa2!M:N,2,0) -> 49 | I21: 2
A22: IPEKYOL | B22: 4 | C22: 10 | D22: SEMI PLAN | E22: Mono-Weekend Edit | F22: =VLOOKUP(E22,Sayfa2!A:B,2,0) -> 1326 | G22: JEAN PANTOLON | H22: =VLOOKUP(G22,Sayfa2!M:N,2,0) -> 13
A23: IPEKYOL | B23: 4 | C23: 10 | D23: SEMI PLAN | E23: Mono-Weekend Edit | F23: =VLOOKUP(E23,Sayfa2!A:B,2,0) -> 1326 | G23: KABAN | H23: =VLOOKUP(G23,Sayfa2!M:N,2,0) -> 16 | I23: 2
A24: IPEKYOL | B24: 4 | C24: 10 | D24: SEMI PLAN | E24: Mono-Weekend Edit | F24: =VLOOKUP(E24,Sayfa2!A:B,2,0) -> 1326 | G24: MONT | H24: =VLOOKUP(G24,Sayfa2!M:N,2,0) -> 17 | I24: 3
A25: IPEKYOL | B25: 4 | C25: 10 | D25: SEMI PLAN | E25: Mono-Weekend Edit | F25: =VLOOKUP(E25,Sayfa2!A:B,2,0) -> 1326 | G25: PANTOLON | H25: =VLOOKUP(G25,Sayfa2!M:N,2,0) -> 14 | I25: 5
A26: IPEKYOL | B26: 4 | C26: 10 | D26: SEMI PLAN | E26: Mono-Weekend Edit | F26: =VLOOKUP(E26,Sayfa2!A:B,2,0) -> 1326 | G26: SUNI KURK | H26: =VLOOKUP(G26,Sayfa2!M:N,2,0) -> 52
A27: IPEKYOL | B27: 4 | C27: 10 | D27: SEMI PLAN | E27: Mono-Weekend Edit | F27: =VLOOKUP(E27,Sayfa2!A:B,2,0) -> 1326 | G27: SWEATSHIRT | H27: =VLOOKUP(G27,Sayfa2!M:N,2,0) -> 27 | I27: 2
A28: IPEKYOL | B28: 4 | C28: 10 | D28: SEMI PLAN | E28: Mono-Weekend Edit | F28: =VLOOKUP(E28,Sayfa2!A:B,2,0) -> 1326 | G28: TISORT | H28: =VLOOKUP(G28,Sayfa2!M:N,2,0) -> 22 | I28: 1
A29: IPEKYOL | B29: 4 | C29: 10 | D29: SEMI PLAN | E29: Mono-Weekend Edit | F29: =VLOOKUP(E29,Sayfa2!A:B,2,0) -> 1326 | G29: TRIKO | H29: =VLOOKUP(G29,Sayfa2!M:N,2,0) -> 23 | I29: 2
A30: IPEKYOL | B30: 4 | C30: 10 | D30: SEMI PLAN | E30: Mono-Weekend Edit | F30: =VLOOKUP(E30,Sayfa2!A:B,2,0) -> 1326 | G30: TULUM | H30: =VLOOKUP(G30,Sayfa2!M:N,2,0) -> 25
A31: IPEKYOL | B31: 4 | C31: 10 | D31: SEMI PLAN | E31: Mono-Weekend Edit | F31: =VLOOKUP(E31,Sayfa2!A:B,2,0) -> 1326 | G31: YELEK | H31: =VLOOKUP(G31,Sayfa2!M:N,2,0) -> 50 | I31: 1
A32: IPEKYOL | B32: 4 | C32: 10 | D32: SEMI PLAN | E32: B-SCT8 | F32: =VLOOKUP(E32,Sayfa2!A:B,2,0) -> 1295 | G32: BLUZ | H32: =VLOOKUP(G32,Sayfa2!M:N,2,0) -> 21 | I32: 1
A33: IPEKYOL | B33: 4 | C33: 10 | D33: SEMI PLAN | E33: B-SCT8 | F33: =VLOOKUP(E33,Sayfa2!A:B,2,0) -> 1295 | G33: CEKET | H33: =VLOOKUP(G33,Sayfa2!M:N,2,0) -> 19 | I33: 2
A34: IPEKYOL | B34: 4 | C34: 10 | D34: SEMI PLAN | E34: B-SCT8 | F34: =VLOOKUP(E34,Sayfa2!A:B,2,0) -> 1295 | G34: ELBISE | H34: =VLOOKUP(G34,Sayfa2!M:N,2,0) -> 20 | I34: 2
A35: IPEKYOL | B35: 4 | C35: 10 | D35: SEMI PLAN | E35: B-SCT8 | F35: =VLOOKUP(E35,Sayfa2!A:B,2,0) -> 1295 | G35: ETEK | H35: =VLOOKUP(G35,Sayfa2!M:N,2,0) -> 12 | I35: 2
A36: IPEKYOL | B36: 4 | C36: 10 | D36: SEMI PLAN | E36: B-SCT8 | F36: =VLOOKUP(E36,Sayfa2!A:B,2,0) -> 1295 | G36: GOMLEK | H36: =VLOOKUP(G36,Sayfa2!M:N,2,0) -> 49 | I36: 1
A37: IPEKYOL | B37: 4 | C37: 10 | D37: SEMI PLAN | E37: B-SCT8 | F37: =VLOOKUP(E37,Sayfa2!A:B,2,0) -> 1295 | G37: JEAN PANTOLON | H37: =VLOOKUP(G37,Sayfa2!M:N,2,0) -> 13
A38: IPEKYOL | B38: 4 | C38: 10 | D38: SEMI PLAN | E38: B-SCT8 | F38: =VLOOKUP(E38,Sayfa2!A:B,2,0) -> 1295 | G38: KABAN | H38: =VLOOKUP(G38,Sayfa2!M:N,2,0) -> 16
A39: IPEKYOL | B39: 4 | C39: 10 | D39: SEMI PLAN | E39: B-SCT8 | F39: =VLOOKUP(E39,Sayfa2!A:B,2,0) -> 1295 | G39: MONT | H39: =VLOOKUP(G39,Sayfa2!M:N,2,0) -> 17
A40: IPEKYOL | B40: 4 | C40: 10 | D40: SEMI PLAN | E40: B-SCT8 | F40: =VLOOKUP(E40,Sayfa2!A:B,2,0) -> 1295 | G40: PANTOLON | H40: =VLOOKUP(G40,Sayfa2!M:N,2,0) -> 14 | I40: 2
...

Sheet Sayfa2
A1: Tema Adı | M1: Column1.Name | N1: Column1.GlValId | O1: Column1.Code
A2: B-BCT2 | B2: 1293 | M2: ATLET | N2: 51 | O2: 050
A3: Mono-Weekend Edit | B3: 1326 | M3: AYAKKABI | N3: 8 | O3: 007
A4: B-SCT8 | B4: 1295 | M4: BIKINI ALT | N4: 34 | O4: 033
A5: MONO-SCT8 | B5: 1297 | M5: BIKINI TAKIM | N5: 33 | O5: 032
A6: B-SCT9 | B6: 1298 | M6: BIKINI UST | N6: 35 | O6: 034
A7: MONO-SCT9 | B7: 1300 | M7: BLUZ | N7: 21 | O7: 020
A8: B-BCT3 | B8: 1301 | M8: BOT-CIZME | N8: 9 | O8: 008
A9: MONO-BCT3 | B9: 1303 | M9: BUSTIYER | N9: 46 | O9: 045
A10: B-SCT10 | B10: 1304 | M10: CANTA | N10: 41 | O10: 040
A11: MONO-SCT10 | B11: 1306 | M11: CEKET | N11: 19 | O11: 018
A12: B-SCT11 | B12: 1307 | M12: CUBUKLU ODA KOKUSU | N12: 31 | O12: 030
A13: MONO-SCT11 | B13: 1309 | M13: DEKORASYON AKSESUARLAR | N13: 2 | O13: 001
... A31: YILBASI-TWS | B31: 1292 | M31: MONT | N31: 17 | O31: 016
A32: B-SCT1 | B32: 1076 | G32: TWS-TEMA 1 | H32: TWIST | I32: 1079 | M32: MUM | N32: 32 | O32: 031
A33: B-SCT2 | B33: 1083 | G33: TWS-TEMA 2 | H33: TWIST | I33: 1080 | M33: ODA SPREYI | N33: 47 | O33: 046
A34: B-SCT3 | B34: 1089 | G34: TWS-TEMA 3 | H34: TWIST | I34: 1087 | M34: PANTOLON | N34: 14 | O34: 013
A35: B-SCT4 | B35: 1095 | G35: TWS-TEMA 4 | H35: TWIST | I35: 1092 | M35: PARDESU | N35: 18 | O35: 017
A36: B-SCT5 | B36: 1102 | G36: TWS-TEMA 5 | H36: TWIST | I36: 1098 | M36: PARFUM | N36: 48 | O36: 047
A37: B-BCT1 | B37: 1112 | G37: TWS-TEMA 6 | H37: TWIST | I37: 1099 | M37: PLAJ URUNLERI | N37: 5 | O37: 004
A38: B-SCT6 | B38: 1108 | G38: TWS-TEMA 7 | H38: TWIST | I38: 1106 | M38: SANDALET | N38: 10 | O38: 009
A39: MONO-SCT1 | B39: 1077 | G39: TWS-TEMA 8 | H39: TWIST | I39: 1110 | M39: SET URUN | N39: 42 | O39: 041
A40: MONO-SCT2 | B40: 1084 | G40: TWS-TEMA 9 | H40: TWIST | I40: 1116 | M40: SIVI SABUN | N40: 29 | O40: 028
A41: MONO-SCT3 | B41: 1090 | G41: B-MONO 1 | H41: TWIST | I41: 1086 | M41: SORT | N41: 26 | O41: 025
A42: B-JEAN P1-IPK | B42: 1094 | G42: B-MONO 2 | H42: TWIST | I42: 1105 | M42: SUNI KURK | N42: 52 | O42: 051
A43: MONO-SCT4 | B43: 1096 | G43: B-MONO 3 | H43: TWIST | I43: 1115 | M43: SWEATSHIRT | N43: 27 | O43: 026
... A52: TWS-TEMA 7 | B52: 1106 | G52: MONO-SCT2 | H52: IPEKYOL | I52: 1084 | M52: YELEK | N52: 50 | O52: 049
A53: TWS-TEMA 8 | B53: 1110 | G53: MONO-SCT3 | H53: IPEKYOL | I53: 1090
A54: TWS-TEMA 9 | B54: 1116 | G54: B-JEAN P1-IPK | H54: IPEKYOL | I54: 1094
A55: B-MONO 1 | B55: 1086 | G55: MONO-SCT4 | H55: IPEKYOL | I55: 1096
A56: B-MONO 2 | B56: 1105 | G56: MONO-SCT5 | H56: IPEKYOL | I56: 1103
A57: B-MONO 3 | B57: 1115 | G57: MONO-SCT6 | H57: IPEKYOL | I57: 1113
